<?xml version="1.0"?>
<robot xmlns:xacro="http://www.ros.org/wiki/xacro">

   <xacro:include filename="inertial_macros.xacro" />

   <link name="base_link" />

   <!-- Chassis -->
   <joint name="chassis_joint" type="fixed">
     <origin xyz="0 0 0" rpy="0 0 0"/>
     <parent link="base_link"/>
     <child link="chassis_link"/>
   </joint>

   <link name="chassis_link">
      <visual>
         <origin xyz="0 0 0.075"/>
         <geometry>
            <box size="0.3 0.3 0.15"/>
         </geometry>
         <material name="chassis_material">
            <color rgba="0.82 0.77 0.91 1.0"/>
         </material>
      </visual>
      <collision>
         <origin xyz="0 0 0.075"/>
         <geometry>
            <box size="0.3 0.3 0.15"/>
         </geometry>
      </collision>
      <xacro:inertial_box mass="0.5" x="0.3" y="0.3" z="0.15">
         <origin xyz="0 0 0.075" rpy="0 0 0"/>
      </xacro:inertial_box>
   </link>

   <!-- Left wheel -->
   <joint name="left_wheel_joint" type="continuous">
     <origin xyz="-0.07 0.175 0" rpy="-${pi/2} 0 0"/>
     <parent link="base_link"/>
     <child link="left_wheel_link"/>
     <axis xyz="0 0 1"/>
   </joint>

   <link name="left_wheel_link">
      <visual>
         <geometry>
            <cylinder radius="0.05" length="0.04"/>
         </geometry>
         <material name="wheel_material">
            <color rgba="0.0 0.0 0.0 1.0"/>
         </material>
      </visual>
      <collision>
         <geometry>
            <cylinder radius="0.05" length="0.04"/>
         </geometry>
      </collision>
      <xacro:inertial_cylinder mass="0.1" length="0.04" radius="0.05">
         <origin xyz="0 0 0" rpy="0 0 0"/>
      </xacro:inertial_cylinder>
   </link>

   <!-- Right wheel -->
   <joint name="right_wheel_joint" type="continuous">
     <origin xyz="-0.07 -0.175 0" rpy="-${pi/2} 0 0"/>
     <parent link="base_link"/>
     <child link="right_wheel_link"/>
     <axis xyz="0 0 1"/>
   </joint>

   <link name="right_wheel_link">
      <visual>
         <geometry>
            <cylinder radius="0.05" length="0.04"/>
         </geometry>
         <material name="wheel_material">
            <color rgba="0.0 0.0 0.0 1.0"/>
         </material>
      </visual>
      <collision>
         <geometry>
            <cylinder radius="0.05" length="0.04"/>
         </geometry>
      </collision>
      <xacro:inertial_cylinder mass="0.1" length="0.04" radius="0.05">
         <origin xyz="0 0 0" rpy="0 0 0"/>
      </xacro:inertial_cylinder>
   </link>

   <!-- Castor wheel -->
   <joint name="castor_wheel_joint" type="fixed">
      <parent link="base_link"/>
      <child link="castor_wheel"/>
      <origin xyz="0.09 0 0"/>
   </joint>

   <link name="castor_wheel">
      <visual>
         <geometry>
            <sphere radius="0.05"/>
         </geometry>
         <material name="castor_material">
               <color rgba="0.62 0.62 0.62 1.0"/>
         </material>
      </visual>
      <collision>
         <geometry>
            <sphere radius="0.05"/>
         </geometry>
      </collision>
      <xacro:inertial_sphere mass="0.1" radius="0.05">
         <origin xyz="0 0 0" rpy="0 0 0"/>
      </xacro:inertial_sphere>
   </link>

</robot>
